Workbook

Sheet Income Statement
D1: Historical | I1: Projected
A2: Breakdown | B2: 2021A | C2: 2022A | D2: 2023A | E2: 2024A | G2: 2025E | H2: 2026E | I2: 2027E | J2: 2028E | K2: 2029E
A3: Total Revenue | B3: 19944600 | C3: 22148900 | D3: 23051900 | E3: 23098500 | G3: ='Revenue Build (FIXED)'!H4 -> 23675.962 | H3: ='Revenue Build (FIXED)'!I4 -> 24741.381 | I3: ='Revenue Build (FIXED)'!J4 -> 25780.519 | J3: ='Revenue Build (FIXED)'!K4 -> 26811.74 | K3: ='Revenue Build (FIXED)'!L4 -> 27750.15
A4: Cost of Operations | B4: 11401900 | C4: 12823800 | D4: 12293800 | E4: 11903400 | G4: =G36*G3 -> 12413.802 | H4: =H36*H3 -> 12861.226 | I4: =I36*I3 -> 13459.331 | J4: =J36*J3 -> 13967.579 | K4: =K36*K3 -> 14472.034
A5: Gross Profit | B5: 8542700 | C5: 9325100 | D5: 10758100 | E5: 11195100 | G5: =G3-G4 -> 11262.161 | H5: =H3-H4 -> 11880.155 | I5: =I3-I4 -> 12321.188 | J5: =J3-J4 -> 12844.161 | K5: =K3-K4 -> 13278.116
A6: Margin | B6: =B5/B3 -> 0.42832145 | C6: =C5/C3 -> 0.42101865 | D6: =D5/D3 -> 0.46669038 | E6: =E5/E3 -> 0.48466784 | G6: =G4/G3 -> 0.52432089 | H6: =H4/H3 -> 0.51982653 | I6: =I4/I3 -> 0.52207371 | J6: =J4/J3 -> 0.52095012 | K6: =K4/K3 -> 0.52151191
A7: Depreciation & Amortization | B7: =B26-B12 -> 572600 | C7: =C26-C12 -> 581100 | D7: 624000 | E7: 622500 | G7: =G37*G3 -> 658.89407 | H7: =H37*H3 -> 649.1165 | I7: =I37*I3 -> 707.66256 | J7: =J37*J3 -> 713.00282 | K7: =K37*K3 -> 761.72797
A8: Operating Expense | B8: 5878000 | C8: 6324500 | D8: 7151700 | E8: 7433200
A9: Selling General and Administrative | B9: 5882000 | C9: 6331600 | D9: 7071000 | E9: 7434500
A10: Research and Development | B10: 115900 | C10: 119300 | D10: 196600 | E10: 217300
A11: Restructuring Charges
A12: EBIT | B12: 2583300 | C12: 2963900 | D12: 3527400 | E12: 3867500
A13: Margin | B13: =B12/B3 -> 0.12952378 | C13: =C12/C3 -> 0.13381703 | D13: =D12/D3 -> 0.15301992 | E13: =E12/E3 -> 0.16743511
A14: Interest Income | B14: 4900 | C14: 8000 | D14: 25200 | E14: 11000
A15: Interest Expense | B15: 334700 | C15: 390800 | D15: 417500 | E15: 415700
A16: Net Interest Income | B16: -340.1 | C16: -395 | D16: -407.3 | E16: -420.4 | G16: -420.4 | H16: -420.4 | I16: -420.4 | J16: -420.4 | K16: -420.4
A17: Other Income Expense | B17: -76 | C17: -32.5 | D17: -89.2 | E17: 110.3 | G17: 43.6 | H17: 43.6 | I17: 43.6 | J17: 43.6 | K17: 43.6
A18: Other Operating Expenses | B18: -4 | C18: -7.1 | D18: 80.7 | E18: -13 | G18: 12.7 | H18: 12.7 | I18: 12.7 | J18: 12.7 | K18: 12.7
A19: EBT | B19: 2248600 | C19: 2573100 | D19: 3109900 | E19: 3451800
A20: Tax Provision | B20: 384200 | C20: 553000 | D20: 721100 | E20: 770400
A21: Net Income | B21: 1864400 | C21: 2020100 | D21: 2388800 | E21: 2681400
A22: Attributable to Non-Controlling Interest | B22: 0 | C22: 0 | D22: 0 | E22: 0 | G22: 0 | H22: 0 | I22: 0 | J22: 0 | K22: 0
A23: Net-Income Attributable to Sherwin-Williams | B23: 1864400 | C23: 2020100 | D23: 2388800 | E23: 2681400
A24: Margin | B24: =B21/B3 -> 0.093478937 | C24: =C21/C3 -> 0.091205432 | D24: =D21/D3 -> 0.10362703 | E24: =E21/E3 -> 0.11608546
A25: Depreciation & Amortization | B25: 309500 | C25: 317100 | D25: 624000 | E25: 622500
A26: EBITDA | B26: 3155900 | C26: 3545000 | D26: 4149900 | E26: 4491500
A27: Margin | B27: 0.1582 | C27: 0.1601 | D27: 0.18 | E27: 0.1944
A28: Earnings Per Share
A29: Basic | B29: 7.1 | C29: 7.83 | D29: 9.35 | E29: 10.68 | G29: 10.68 | H29: 10.68 | I29: 10.68 | J29: 10.68 | K29: 10.68
A30: Diluted | B30: 6.98 | C30: 7.72 | D30: 9.25 | E30: 10.55 | G30: 10.55 | H30: 10.55 | I30: 10.55 | J30: 10.55 | K30: 10.55
A31: Shares Outstanding
A32: Basic | B32: 262.5 | C32: 251 | D32: 255.4 | E32: 258 | G32: 258 | H32: 258 | I32: 258 | J32: 258 | K32: 258
A33: Diluted | B33: 267.1 | C33: 254.1 | D33: 258.3 | E33: 261.8 | G33: 261.8 | H33: 261.8 | I33: 261.8 | J33: 261.8 | K33: 261.8
A35: Forecast
A36: Cost of Operations | B36: =B4/B3 -> 0.57167855 | C36: =C4/C3 -> 0.57898135 | D36: =D4/D3 -> 0.53330962 | E36: =E4/E3 -> 0.51533216 | G36: =AVERAGE(D36,E36) -> 0.52432089 | H36: =AVERAGE(E36,G36) -> 0.51982653 | I36: =AVERAGE(G36,H36) -> 0.52207371 | J36: =AVERAGE(H36,I36) -> 0.52095012 | K36: =AVERAGE(I36,J36) -> 0.52151191
A37: Depreciation, Ammoritzaition and Deplection | B37: =B7/B3 -> 0.028709525 | C37: =C7/C3 -> 0.026236066 | D37: =D7/D3 -> 0.027069352 | E37: =E7/E3 -> 0.026949802 | G37: =AVERAGE(B37,E37) -> 0.027829664 | H37: =AVERAGE(C37,F37) -> 0.026236066 | I37: =AVERAGE(D37,G37) -> 0.027449508 | J37: =AVERAGE(E37,H37) -> 0.026592934 | K37: =AVERAGE(F37,I37) -> 0.027449508
A38: Selling, General, and Administrative | B38: =B9/B3 -> 0.29491692 | C38: =C9/C3 -> 0.28586521 | D38: =D9/D3 -> 0.30674261 | E38: =E9/E3 -> 0.32186073 | G38: =AVERAGE(B38,E38) -> 0.30838882 | H38: =AVERAGE(C38,F38) -> 0.28586521 | I38: =AVERAGE(D38,G38) -> 0.30756572 | J38: =AVERAGE(E38,H38) -> 0.30386297 | K38: =AVERAGE(F38,I38) -> 0.30756572
A39: Research and Development | B39: =B10/B3 -> 0.0058110967 | C39: =C10/C3 -> 0.005386272 | D39: =D10/D3 -> 0.0085285812 | E39: =E10/E3 -> 0.0094075373 | G39: =AVERAGE(B39,E39) -> 0.007609317 | H39: =AVERAGE(C39,F39) -> 0.005386272 | I39: =AVERAGE(D39,G39) -> 0.0080689491 | J39: =AVERAGE(E39,H39) -> 0.0073969046 | K39: =AVERAGE(F39,I39) -> 0.0080689491
A40: Interest Expense | B40: =B15/B3 -> 0.016781485 | C40: =C15/C3 -> 0.017644217 | D40: =D15/D3 -> 0.018111305 | E40: =E15/E3 -> 0.01799684 | G40: =AVERAGE(B40,E40) -> 0.017389162 | H40: =AVERAGE(C40,F40) -> 0.017644217 | I40: =AVERAGE(D40,G40) -> 0.017750234 | J40: =AVERAGE(E40,H40) -> 0.017820528 | K40: =AVERAGE(F40,I40) -> 0.017750234
A41: Taxes | B41: 0.21 | C41: 0.21 | D41: 0.21 | E41: 0.21 | G41: 0.21 | H41: 0.21 | I41: 0.21 | J41: 0.21 | K41: 0.21
...

Sheet Revenue Build (FIXED)
G2: Historical | H2: Projected
D3: 2021A | E3: 2022A | F3: 2023A | G3: 2024A | H3: 2025E | I3: 2026E | J3: 2027E | K3: 2028E | L3: 2029E
B4: Net Sales | D4: 19994.6 | E4: 22148.9 | F4: 23051.9 | G4: 23098.5 | H4: =G4*(1+H31) -> 23675.962 | I4: =H4*(1+I31) -> 24741.381 | J4: =I4*(1+J31) -> 25780.519 | K4: =J4*(1+K31) -> 26811.74 | L4: =K4*(1+L31) -> 27750.15
B5: YoY Growth | E5: 11.1 | F5: 4.1 | G5: 0.2
B7: Paint Store Group:
B8: Net Sales | D8: 10616.2 | E8: 11963.3 | F8: 12839.5 | G8: 13188 | H8: =G8*(1+H34) -> 13583.64 | I8: =H8*(1+I34) -> 14126.986 | J8: =I8*(1+J34) -> 14621.43 | K8: =J8*(1+K34) -> 15060.073 | L8: =K8*(1+L34) -> 15436.575
B9: Intersegment Tranfers | D9: - | E9: - | F9: - | G9: - | H9: - | I9: - | J9: - | K9: - | L9: -
B10: Total Paint Store Group | D10: 10616.2 | E10: 11963.3 | F10: =F8 -> 12839.5 | G10: =G8 -> 13188 | H10: =G10*(1+H36) -> 13583.64 | I10: =H10*(1+I36) -> 14126.986 | J10: =I10*(1+J36) -> 14621.43 | K10: =J10*(1+K36) -> 15060.073 | L10: =K10*(1+L36) -> 15436.575
B12: Consumer Brands Group:
B13: Net Sales | D13: 3322.4 | E13: 3388.4 | F13: 3365.6 | G13: 3108 | H13: =G13*(1+H38) -> 3045.84 | I13: =H13*(1+I38) -> 3045.84 | J13: =I13*(1+J38) -> 3091.5276 | K13: =J13*(1+K38) -> 3153.3582 | L13: =K13*(1+L38) -> 3216.4253
B14: Less Intersegment Tranfers | D14: -4183.6 | E14: -5214.8 | F14: -5234 | G14: -5304.3 | H14: =G14*(1+H39) -> -5198.214 | I14: =H14*(1+I39) -> -5198.214 | J14: =I14*(1+J39) -> -5276.1872 | K14: =J14*(1+K39) -> -5381.711 | L14: =K14*(1+L39) -> -5489.3452
B15: Total Consumer Brands Group | D15: =D13+D14 -> -861.2 | E15: =E13+E14 -> -1826.4 | F15: =F13+F14 -> -1868.4 | G15: =G13+G14 -> -2196.3 | H15: =G15*(1+H40) -> -2152.374 | I15: =H15*(1+I40) -> -2152.374 | J15: =I15*(1+J40) -> -2184.6596 | K15: =J15*(1+K40) -> -2228.3528 | L15: =K15*(1+L40) -> -2272.9199
B17: Performance Coating Group:
B18: Net Sales | D18: 6003.8 | E18: 6793.5 | F18: 6843.1 | G18: 6797.3 | H18: =G18*(1+H43) -> 6933.246 | I18: =H18*(1+I43) -> 7141.2434 | J18: =I18*(1+J43) -> 7391.1869 | K18: =J18*(1+K43) -> 7686.8344 | L18: =K18*(1+L43) -> 7994.3077
B19: Less Intersegment Tranfers | D19: -149.7 | E19: -203.7 | F19: -197.8 | G19: -56.8 | H19: =G19*(1+H44) -> -57.936 | I19: =H19*(1+I44) -> -59.67408 | J19: =I19*(1+J44) -> -268.53336 | K19: =J19*(1+K44) -> -279.27469 | L19: =K19*(1+L44) -> -290.44568
B20: Total Performance Coating Group | D20: =D18+D19 -> 5854.1 | E20: =E18+E19 -> 6589.8 | F20: =F18+F19 -> 6645.3 | G20: =G18+G19 -> 6740.5 | H20: =G20*(1+H45) -> 6875.31 | I20: =H20*(1+I45) -> 7081.5693 | J20: =I20*(1+J45) -> 31867.062 | K20: =J20*(1+K45) -> 33141.744 | L20: =K20*(1+L45) -> 34467.414
B22: Administrative:
B23: Net Sales | D23: 2.2 | E23: 3.7 | F23: 3.7 | G23: 5.2 | H23: =G23*(1+H48) -> 5.46 | I23: =H23*(1+I48) -> 5.6238 | J23: =I23*(1+J48) -> 5.764395 | K23: =J23*(1+K48) -> 5.8796829 | L23: =K23*(1+L48) -> 5.9972766
B24: Less Intersegment Tranfers | D24: -4333.3 | E24: -5418.5 | F24: -5431.8 | G24: -5361.1 | H24: =G24*(1+H49) -> -5629.155 | I24: =H24*(1+I49) -> -5798.0297 | J24: =I24*(1+J49) -> -5942.9804 | K24: =J24*(1+K49) -> -6061.84 | L24: =K24*(1+L49) -> -6183.0768
B25: Total Administrative | D25: =D23+D24 -> -4331.1 | E25: =E23+E24 -> -5414.8 | F25: =F23+F24 -> -5428.1 | G25: =G23+G24 -> -5355.9 | H25: =G25*(1+H50) -> -5623.695 | I25: =H25*(1+I50) -> -5792.4059 | J25: =I25*(1+J50) -> -5937.216 | K25: =J25*(1+K50) -> -6055.9603 | L25: =K25*(1+L50) -> -6177.0795
D30: 2021A | E30: 2022A | F30: 2023A | G30: 2024A | H30: 2025E | I30: 2026E | J30: 2027E | K30: 2028E | L30: 2029E
B31: Revenue | D31: 0 | E31: =(E4/D4)-1 -> 0.10774409 | F31: =(F4/E4)-1 -> 0.040769519 | G31: =(G4/F4)-1 -> 0.0020215253 | H31: 0.025 | I31: 0.045 | J31: 0.042 | K31: 0.04 | L31: 0.035
B32: YoY Growth | D32: 0
B33: Paint Store Group:
B34: Net Sales | D34: 0 | E34: =(E8/D8)-1 -> 0.12689098 | F34: =F8/E8 -> 1.0732407 | G34: =G8/F8 -> 1.0271428 | H34: 0.03 | I34: 0.04 | J34: 0.035 | K34: 0.03 | L34: 0.025
B35: Intersegment Tranfers | D35: 0 | E35: =(E9/D9)-1 -> #VALUE! | F35: =(F9/E9)-1 -> #VALUE! | G35: =(G9/F9)-1 -> #VALUE! | H35: =(H9/G9)-1 -> #VALUE!
B36: Total Paint Store Group | D36: 0 | E36: =(E10/D10)-1 -> 0.12689098 | F36: =(F10/E10)-1 -> 0.073240661 | G36: =(G10/F10)-1 -> 0.027142802 | H36: 0.03 | I36: 0.04 | J36: 0.035 | K36: 0.03 | L36: 0.025
B37: Consumer Brands Group:
B38: Net Sales | D38: 0 | E38: =(E13/D13)-1 -> 0.019865158 | F38: =(F13/E13)-1 -> -0.0067288396 | G38: =(G13/F13)-1 -> -0.076539101 | H38: -0.02 | I38: 0 | J38: 0.015 | K38: 0.02 | L38: 0.02
B39: Intersegment Tranfers | D39: 0 | E39: =(E14/D14)-1 -> 0.24648628 | F39: =(F14/E14)-1 -> 0.0036818286 | G39: =(G14/F14)-1 -> 0.01343141 | H39: -0.02 | I39: 0 | J39: 0.015 | K39: 0.02 | L39: 0.02
B40: Total Consumer Brands Group | D40: 0 | E40: =(E15/D15)-1 -> 1.1207617 | F40: =(F15/E15)-1 -> 0.022996058 | G40: =(G15/F15)-1 -> 0.17549775 | H40: -0.02 | I40: 0 | J40: 0.015 | K40: 0.02 | L40: 0.02
B42: Performance Coating Group: | D42: 0
B43: Net Sales | D43: 0 | E43: =(E18/D18)-1 -> 0.13153336 | F43: =(F18/E18)-1 -> 0.0073010966 | G43: =(G18/F18)-1 -> -0.0066928731 | H43: 0.02 | I43: 0.03 | J43: 0.035 | K43: 0.04 | L43: 0.04
B44: Intersegment Tranfers | D44: 0 | E44: =(E19/D19)-1 -> 0.36072144 | F44: =(F19/E19)-1 -> -0.028964163 | G44: =(G19/F19)-1 -> -0.71284125 | H44: 0.02 | I44: 0.03 | J44: 3.5 | K44: 0.04 | L44: 0.04
B45: Total Performance Coating Group | D45: 0 | E45: =(E20/D20)-1 -> 0.12567261 | F45: =(F20/E20)-1 -> 0.0084221069 | G45: =(G20/F20)-1 -> 0.014325915 | H45: 0.02 | I45: 0.03 | J45: 3.5 | K45: 0.04 | L45: 0.04
B47: Administrative: | D47: 0
B48: Net Sales | D48: 0 | E48: =(E23/D23)-1 -> 0.68181818 | F48: =(F23/E23)-1 -> 0 | G48: =(G23/F23)-1 -> 0.40540541 | H48: 0.05 | I48: 0.03 | J48: 0.025 | K48: 0.02 | L48: 0.02
B49: Intersegment Tranfers | D49: 0 | E49: =(E24/D24)-1 -> 0.2504327 | F49: =(F24/E24)-1 -> 0.0024545538 | G49: =(G24/F24)-1 -> -0.013015943 | H49: 0.05 | I49: 0.03 | J49: 0.025 | K49: 0.02 | L49: 0.02
B50: Total Net Sales and Intersegment Tranfers | D50: 0 | E50: =(E25/D25)-1 -> 0.25021357 | F50: =(F25/E25)-1 -> 0.0024562311 | G50: =(G25/F25)-1 -> -0.013301155 | H50: 0.05 | I50: 0.03 | J50: 0.025 | K50: 0.02 | L50: 0.02

Sheet Revenue Build
G2: Historical | I2: Projected
D3: 2021A | E3: 2022A | F3: 2023A | G3: 2024A | H3: 2025E | I3: 2026E | J3: 2027E | K3: 2028E | L3: 2029E | O3: USE SEC EDGAR
B4: Revenue | D4: 19944600 | E4: 22148900 | F4: 23051900 | G4: 23098500
B5: Net Sales | D5: 19994.6 | E5: 22148.9 | F5: 23051.9 | G5: 23098.5
B6: YoY Growth | E6: 11.1 | F6: 4.1 | G6: 0.2
B8: Paint Store Group:
B9: Net Sales | D9: 10616.2 | E9: 11963.3 | F9: 12839.5 | G9: 13188
B10: Intersegment Tranfers | D10: - | E10: - | F10: - | G10: - | H10: - | I10: - | J10: - | K10: - | L10: -
B11: Total Net Sales and Intersegment Tranfers | D11: 10616.2 | E11: 11963.3 | F11: =F9 -> 12839.5 | G11: =G9 -> 13188 | H11: =H9 -> 0 | I11: =I9 -> 0 | J11: =J9 -> 0 | K11: =K9 -> 0 | L11: =L9 -> 0
B13: Segment Profit
B14: Cost of Goods Sold | D14: - | E14: 5826.8 | F14: 5794.4 | G14: 5900.8
B15: Selling, General, and Administrative expenses | D15: - | E15: 3810.1 | F15: 4211.5 | G15: 4405.6
B16: Other Segment Items | D16: - | E16: -21.7 | F16: -27.2 | G16: -21
B17: Income before Income Taxes | E17: =E11-(E14+E15+E16) -> 2348.1 | F17: =F11-(F14+F15+F16) -> 2860.8 | G17: =G11-(G14+G15+G16) -> 2902.6 | H17: =H11-(H14+H15+H16) -> 0 | I17: =I11-(I14+I15+I16) -> 0 | J17: =J11-(J14+J15+J16) -> 0 | K17: =K11-(K14+K15+K16) -> 0 | L17: =L11-(L14+L15+L16) -> 0
B18: % of Net Sales | E18: =E17/E11 -> 0.19627528 | F18: =F17/F11 -> 0.22281241 | G18: =G17/G11 -> 0.22009402 | H18: =H17/H11 -> #DIV/0! | I18: =I17/I11 -> #DIV/0! | J18: =J17/J11 -> #DIV/0! | K18: =K17/K11 -> #DIV/0! | L18: =L17/L11 -> #DIV/0!
B20: Consumer Brands Group:
B21: Net Sales | D21: 3322.4 | E21: 3388.4 | F21: 3365.6 | G21: 3108
B22: Intersegment Tranfers | D22: 4183.6 | E22: 5214.8 | F22: 5234 | G22: 5304.3
B23: Total Net Sales and Intersegment Tranfers | D23: =D21+D22 -> 7506 | E23: =E21+E22 -> 8603.2 | F23: =F21+F22 -> 8599.6 | G23: =G21+G22 -> 8412.3 | H23: =H21+H22 -> 0 | I23: =I21+I22 -> 0 | J23: =J21+J22 -> 0 | K23: =K21+K22 -> 0 | L23: =L21+L22 -> 0
B25: Cost of Goods Sold | E25: 7454.8 | F25: 7311.9 | G25: 6943.5
B26: Selling, General, and Administrative expenses | E26: 817.8 | F26: 882.3 | G26: 863.1
B27: Interest Expense | E27: - | F27: - | G27: 1.4
B28: Other Segment Items | E28: 16.4 | F28: 96.1 | G28: 14.4
B29: Income before Income Taxes | E29: =E23-E25-E26-E28 -> 314.2 | F29: =F23-F25-F26-F28 -> 309.3 | G29: =G23-G25-G26-G28-G27 -> 589.9 | H29: =H23-H25-H26-H28 -> 0 | I29: =I23-I25-I26-I28 -> 0 | J29: =J23-J25-J26-J28 -> 0 | K29: =K23-K25-K26-K28 -> 0 | L29: =L23-L25-L26-L28 -> 0
B30: % of Net Sales | E30: 0.093 | F30: 0.092 | G30: 0.19 | H30: 0.093 | I30: 0.093 | J30: 0.093 | K30: 0.093 | L30: 0.093
B32: Performance Coating Group:
B33: Net Sales | D33: 6003.8 | E33: 6793.5 | F33: 6843.1 | G33: 6797.3
B34: Intersegment Tranfers | D34: 149.7 | E34: 203.7 | F34: 197.8 | G34: 56.8
B35: Total Net Sales and Intersegment Tranfers | D35: =D33+D34 -> 6153.5 | E35: =E33+E34 -> 6997.2 | F35: =F33+F34 -> 7040.9 | G35: =G33+G34 -> 6854.1 | H35: =H33+H34 -> 0 | I35: =I33+I34 -> 0 | J35: =J33+J34 -> 0 | K35: =K33+K34 -> 0 | L35: =L33+L34 -> 0
B37: Cost of Goods Sold | E37: 4965.4 | F37: 4606.9 | G37: 4406.5
B38: Selling, General, and Administrative expenses | E38: 1275.6 | F38: 1415.5 | G38: 1443
B39: Other Segment Items | E39: 21.3 | F39: 26.9 | G39: -23.3
B40: Income before Income Taxes | E40: =E35-E37-E38-E39 -> 734.9 | F40: =F35-F37-F38-F39 -> 991.6 | G40: =G35-G37-G38-G39 -> 1027.9 | H40: =H35-H37-H38-H39 -> 0 | I40: =I35-I37-I38-I39 -> 0 | J40: =J35-J37-J38-J39 -> 0 | K40: =K35-K37-K38-K39 -> 0 | L40: =L35-L37-L38-L39 -> 0
B41: % of Net Sales | E41: 0.108 | F41: 0.145 | G41: 0.151 | H41: 0.108 | I41: 0.108 | J41: 0.108 | K41: 0.108 | L41: 0.108
B43: Administrative:
B44: Net Sales | D44: 2.2 | E44: 3.7 | F44: 3.7 | G44: 5.2
B45: Intersegment Tranfers | D45: -4333.3 | E45: -5418.5 | F45: -5431.8 | G45: -5361.1
B46: Total Net Sales and Intersegment Tranfers | D46: =D44+D45 -> -4331.1 | E46: =E44+E45 -> -5414.8 | F46: =F44+F45 -> -5428.1 | G46: =G44+G45 -> -5355.9 | H46: =H44+H45 -> 0 | I46: =I44+I45 -> 0 | J46: =J44+J45 -> 0 | K46: =K44+K45 -> 0 | L46: =L44+L45 -> 0
B48: Cost of Goods Sold | E48: -5423.2 | F48: -5419.4 | G48: -5347.4
B49: Selling, General, and Administrative expenses | E49: 428.1 | F49: 556.1 | G49: 710.4
...

Sheet Cash Flow Statement
A1: Cash Flow Statements | D1: Historical
B2: 2021A | C2: 2022A | D2: 2023A | E2: 2024A
A3: Cash provided by operating activities:
A4: Net income | B4: 1864.4 | C4: 2020.1 | D4: 2388.8 | E4: 2681.4
A5: Depreciation, amortization, depletion and accretion | B5: 263.1 | C5: 264 | D5: 292.3 | E5: 297.4
A6: Non‑cash interest expense | B6: 334.7 | C6: 390.8 | D6: 417.5 | E6: 415.7
A7: Stock‑based compensation | B7: 97.7 | C7: 99.7 | D7: 115.9 | E7: 138.1
A8: Deferred tax provision (benefit) | B8: 80.3 | C8: 144.8 | D8: 88.9 | E8: 74.9
A9: Provision for doubtful accounts | B9: 33.8 | C9: 65.3 | D9: 67.9 | E9: 69.5
A10: Loss on extinguishment of debt | B10: 1.4 | C10: 0.0 | D10: 12.8 | E10: 0.0
A11: (Gain) loss on disposition of assets & impairments, net | B11: 6.1 | C11: 10.7 | D11: 0.9 | E11: 49.9
A12: Environmental adjustments | B12: 7.1 | C12: 80.7 | D12: 1.3 | E12: 1.3
A13: Other non‑cash items | B13: 43.9 | C13: 6.8 | D13: 7 | E13: 6.1
A14: Accounts receivable | B14: 200.2 | C14: 10.7 | D14: 85.6 | E14: 10.7
A15: Prepaid expenses and other assets | B15: 32.5 | C15: 31.5 | D15: 31.5 | E15: 31.5
A16: Accounts payable | B16: 46.6 | C16: 21.8 | D16: 241.1 | E16: 21.8
A17: Other tabites | B17: 43.9 | C17: 6.8 | D17: 7 | E17: 6.1
A18: Cash provided by operating activities (TOTAL) | B18: 3055.7 | C18: 3153.7 | D18: 3759.5 | E18: 3804.4
A19: Purchases of property and equipment | B19: 372 | C19: 644.5 | D19: 888.4 | E19: 1070
A20: Proceeds from sales of property and equipment | B20: 14.8 | C20: 33.2 | D20: 70.1 | E20: 11.6
A21: Cash used in acquisitions and investments | B21: 210.9 | C21: 1003.1 | D21: 264.7 | E21: 78.9
A22: Cash received from business divestitures | B22: 122.5 | C22: 0.0 | D22: 103.7 | E22: 0.0
A23: Other (investing) | B23: 6.8 | C23: 59 | D23: 60 | E23: 59
A24: Cash used in investing activities (TOTAL) | B24: -438.8 | C24: 1673.4 | D24: 1673.4 | E24: -1196.3
A25: Proceeds from credit facilities & notes payable | B25: 763.9 | C25: 214.4 | D25: 603.9 | E25: 288.6
A26: Proceeds from issuance of senior notes | B26: 999.7 | C26: 0.0 | D26: 0.0 | E26: 848.7
A27: Payments of credit facilities & notes payable | B27: 11.5 | C27: 7.3 | D27: 0.0 | E27: 8.6
A28: Issuances of common stock, net | B28: 90 | C28: 30 | D28: 30 | E28: 30
A29: Purchases of common stock for treasury | B29: 10.1 | C29: 3.4 | D29: 5.6 | E29: 5.2
A30: Cash dividends | B30: 587.1 | C30: 618.5 | D30: 623.7 | E30: 723.4
A31: Cash provided by (used in) financing activities (TOTAL) | B31: 1244.9 | C31: -384.8 | D31: 4.6 | E31: 430.1
A32: Effect of foreign‑exchange rate changes on cash | B32: 9.8 | C32: 28.8 | D32: 14.1 | E32: 12.2
A33: Increase (decrease) in cash | B33: 60.9 | C33: 33.1 | D33: 78.0 | E33: 66.4
A34: Cash at the beginning of the year | B34: 226.6 | C34: 165.7 | D34: 198.8 | E34: 276.8
A35: Cash at the end of the year | B35: 165.7 | C35: 198.8 | D35: 276.8 | E35: 210.4

Sheet Balance Sheet
B2: Balance Sheet | E2: Historical
B3: ( $ In millions) | C3: 2020A | D3: 2021A | E3: 2022A | F3: 2023A | G3: 2024A
B5: Assets:
B6: Current Assets:
B7: Cash and cash equivalents | C7: 226.6 | D7: 165.7 | E7: 198.8 | F7: 276.8 | G7: 210.4
B8: Accounts recievable, less allowance | C8: 2078.1 | D8: 2352.4 | E8: 2563.6 | F8: 2467.9 | G8: 2388.8
B9: Inventories | C9: 1804.1 | D9: 1927.2 | E9: 2626.5 | F9: 2329.8 | G9: 2288.1
B10: Other current assets | C10: 482.6 | D10: 608.4 | E10: 518.8 | F10: 438.4 | G10: 513.5
B11: Total current assets | C11: =C7+C8+C9+C10 -> 4591.4 | D11: =D7+D8+D9+D10 -> 5053.7 | E11: =E7+E8+E9+E10 -> 5907.7 | F11: =F7+F8+F9+F10 -> 5512.9 | G11: =G7+G8+G9+G10 -> 5400.8
B12: Property, plant and equipment, net | C12: 1834.5 | D12: 1867.3 | E12: 2207 | F12: 2836.8 | G12: 3533.2
B13: Goodwill | C13: 7049.1 | D13: 7134.6 | E13: 7583.2 | F13: 7626 | G13: 7580.1
B14: Intangible assets, net | C14: 4471.2 | D14: 4001.5 | E14: 4002 | F14: 3880.5 | G14: 3533.2
B15: Operating lease right-of-use assets | C15: 1761.1 | D15: 1820.6 | E15: 1866.8 | F15: 1887.4 | G15: 1953.8
B16: Other assets | C16: 694.3 | D16: 789 | E16: 1027.3 | F16: 1210.8 | G16: 1631.5
B17: Total Assets | C17: =C11+C12+C13+C14+C15+C16 -> 20401.6 | D17: =D11+D12+D13+D14+D15+D16 -> 20666.7 | E17: =E11+E12+E13+E14+E15+E16 -> 22594 | F17: =F11+F12+F13+F14+F15+F16 -> 22954.4 | G17: =G11+G12+G13+G14+G15+G16 -> 23632.6
B19: Liabilities and Shareholders' Equity:
B20: Current liabilities:
B21: Short-term borrowings | C21: 0.1 | D21: 763.5 | E21: 978.1 | F21: 374.2 | G21: 662.4
B22: Accounts payable | C22: 2117.8 | D22: 2403 | E22: 2436.5 | F22: 2315 | G22: 2253.2
B23: Compensation and taxes withheld | C23: 752.7 | D23: 716.6 | E23: 784.5 | F23: 862.7 | G23: 842.8
B24: Accrued taxes | C24: 183.5 | D24: 160.3 | E24: 197.4 | F24: 197.4 | G24: 174.3
B25: Current portion of long-term debt | C25: 25.1 | D25: 260.6 | E25: 0.6 | F25: 1098.8 | G25: 1049.2
B26: Current portion of operating lease liabilities | C26: 387.3 | D26: 409.7 | E26: 425.3 | F26: 449.3 | G26: 466.6
B27: Other accruals | C27: 1127.9 | D27: 1005.8 | E27: 1138.3 | F27: 1329.5 | G27: 1360.2
B28: Total current liabilities | C28: =C21+C22+C23+C24+C25+C26+C27 -> 4594.4 | D28: =D21+D22+D23+D24+D25+D26+D27 -> 5719.5 | E28: =E21+E22+E23+E24+E25+E26+E27 -> 5960.7 | F28: =F21+F22+F23+F24+F25+F26+F27 -> 6626.9 | G28: =G21+G22+G23+G24+G25+G26+G27 -> 6808.7
B29: Long-term debt | C29: 8266.9 | D29: 8590.9 | E29: 9591 | F29: 8377.9 | G29: 8176.8
B30: Postretirement benefits other than pensions | C30: 275.6 | D30: 259.4 | E30: 139.3 | F30: 133.2 | G30: 120.7
B31: Deferred income taxes | C31: 846.1 | D31: 768.2 | E31: 681.6 | F31: 683.1 | G31: 607.5
B32: Long-term operating lease liabilities | C32: 1434.1 | D32: 1470.7 | E32: 1512.9 | F32: 1509.5 | G32: 1558.3
B33: Other long-term liabilities | C33: 1373.7 | D33: 1420.8 | E33: 1606.4 | F33: 1908 | G33: 2309.4
B34: Shareholders' equity:
B35: Common Stock | C35: 89.9 | D35: 90.8 | E35: 91.2 | F35: 91.8 | G35: 92.5
B36: Other capital | C36: 3491.4 | D36: 3793 | E36: 3963.9 | F36: 4193.6 | G36: 4576.2
B37: Retained earnings | C37: 844.3 | D37: 2121.7 | E37: 3523.2 | F37: 5288.3 | G37: 7246.3
B38: Treasury stock, at cost | C38: -96.5 | D38: -2869.9 | E38: -3775.6 | F38: -5233.6 | G38: -6988.6
B39: Accumulated other comprehensive loss | C39: -718.3 | D39: -698.4 | E39: -700.6 | F39: -624.3 | G39: -875.2
B40: Total shareholders' equity | C40: =C35+C36+C37+C38+C39 -> 3610.8 | D40: =D35+D36+D37+D38+D39 -> 2437.2 | E40: =E35+E36+E37+E38+E39 -> 3102.1 | F40: =F35+F36+F37+F38+F39 -> 3715.8 | G40: =G35+G36+G37+G38+G39 -> 4051.2
B41: Total Liabilities and Shareholders' Equity | C41: =C28+C29+C30+C31+C32+C33+C40 -> 20401.6 | D41: =D28+D29+D30+D31+D32+D33+D40 -> 20666.7 | E41: =E28+E29+E30+E31+E32+E33+E40 -> 22594 | F41: =F28+F29+F30+F31+F32+F33+F40 -> 22954.4 | G41: =G28+G29+G30+G31+G32+G33+G40 -> 23632.6

Sheet Comparisons
B1: As of (10-2-2025) | D1: Market Cap | E1: EV | G1: LTM
B2: Company | C2: Ticker | D2: ($MM | E2: EV ($MM) | F2: EV/EBITDA | G2: EV/Revenue | H2: P|E
B3: Linde plc | C3: NYSE: LIN | D3: 220.14 | E3: 241.28 | F3: 18.48x | G3: 7.26x | H3: 33.37x | I3: Yahoo Finance
B4: PPG Industries | C4: NYSE: PPG | D4: 23.59 | E4: 29.91 | F4: 11.99x | G4: 1.91x | H4: 18.9x | I4: Yahoo Finance
B5: RPM International | C5: NYSE: RPM | D5: 14.91 | E5: 17.62 | F5: 16.01x | G5: 2.34x | H5: 21.73x | I5: Yahoo Finance
B6: Masco Corporation | C6: NYSE: MAS | D6: 14.86 | E6: 17.7 | F6: 14.28x | G6: 2.31x | H6: 18.83x | I6: Yahoo Finance
B7: Axalta Coating Systems | C7: NYSE: AXTA | D7: 6.11 | E7: 8.9 | F7: 8.63x | G7: 1.71x | H7: 13.82x | I7: Yahoo Finance
E9: Average | F9: 13.878x | G9: 3.106x | H9: 21.33x
E10: Median | F10: 14.28x | G10: 2.31x | H10: 18.9x
E11: Max | F11: 18.48x | G11: 7.26x | H11: 33.37x
E12: Min | F12: 8.63x | G12: 1.71x | H12: 13.82x

Sheet Valuations
B1: EV/EBITDA | E1: EV/Revenue | H1: P / E
B2: Valuation Summary | E2: Valuation Summary | H2: Valuation Summary
B4: EBITDA | C4: 4491.5 | E4: Revenue | F4: ='Income Statement'!E3 -> 23098500 | H4: EPS | I4: 10.68
B5: Multiple | C5: 14.28x | E5: Multiple | F5: =Comparisons!G10 -> 2.31x | H5: Multiple | I5: 33.2x
B7: Total Enterprise Value | C7: 64138620 | E7: Total Enterprise Value | F7: 53357.54 | H7: Total Enterprise Value 100,949.24
B8: (-)Debt | C8: 9888.4 | E8: (-) Debt | F8: 9888.4 | H8: (-)Debt | I8: 9888.4
B9: (+)Cash | C9: 210.4 | E9: (+) Cash | F9: 210.4 | H9: (+)Cash | I9: 210.4
B10: Total Equity Value | C10: =C7-C8+C9 -> 64128942 | E10: Total Equity Value | F10: =F7+F9-F8 -> 43679.54 | H10: Total Equity Value | I10: 91481.64
B11: Shares Outstanding | C11: 258 | E11: Shares Outstanding | F11: 258 | H11: Shares Outstanding | I11: 258
B13: Implied Share Price | C13: =C10/C11 -> 248561.79 | E13: Implied Share Price | F13: 128.41 | H13: Implied Share Price | I13: 354.576
B14: Current Price (As of 11/9/25) | C14: 340.16 | E14: Current Price (As of 11/9/25) | F14: 340.16 | H14: Current Price (As of 11/9/25) | I14: 340.16
B15: Upside (Downside) | C15: 0.2692 | E15: Upside (Downside) | F15: 0.6225 | H15: Upside (Downside) | I15: 0.0424
